<?xml version="1.0" encoding="UTF-8"?>
<!-- Generated by org.testng.reporters.JUnitReportReporter -->
<testsuite hostname="chaitanya-PC" name="datadriventesting.DatadrivenTest" tests="4" failures="3" timestamp="11 Apr 2017 06:54:33 GMT" time="315.385" errors="1">
  <testcase name="login" time="134.455" classname="datadriventesting.DatadrivenTest">
    <error type="org.openqa.selenium.WebDriverException" message="Failed to connect to binary FirefoxBinary(C:\Program Files (x86)\Mozilla Firefox\firefox.exe) on port 7055; process output follows: 

Build info: version: &#039;2.53.1&#039;, revision: &#039;a36b8b1&#039;, time: &#039;2016-06-30 17:37:03&#039;
System info: host: &#039;chaitanya-PC&#039;, ip: &#039;192.168.145.1&#039;, os.name: &#039;Windows 7&#039;, os.arch: &#039;amd64&#039;, os.version: &#039;6.1&#039;, java.version: &#039;1.8.0_121&#039;
Driver info: driver.version: FirefoxDriver">
      <![CDATA[org.openqa.selenium.WebDriverException: Failed to connect to binary FirefoxBinary(C:\Program Files (x86)\Mozilla Firefox\firefox.exe) on port 7055; process output follows: 

Build info: version: '2.53.1', revision: 'a36b8b1', time: '2016-06-30 17:37:03'
System info: host: 'chaitanya-PC', ip: '192.168.145.1', os.name: 'Windows 7', os.arch: 'amd64', os.version: '6.1', java.version: '1.8.0_121'
Driver info: driver.version: FirefoxDriver
	at org.openqa.selenium.firefox.internal.NewProfileExtensionConnection.start(NewProfileExtensionConnection.java:124)
	at org.openqa.selenium.firefox.FirefoxDriver.startClient(FirefoxDriver.java:271)
	at org.openqa.selenium.remote.RemoteWebDriver.<init>(RemoteWebDriver.java:119)
	at org.openqa.selenium.firefox.FirefoxDriver.<init>(FirefoxDriver.java:218)
	at org.openqa.selenium.firefox.FirefoxDriver.<init>(FirefoxDriver.java:211)
	at org.openqa.selenium.firefox.FirefoxDriver.<init>(FirefoxDriver.java:207)
	at org.openqa.selenium.firefox.FirefoxDriver.<init>(FirefoxDriver.java:120)
	at datadriventesting.DatadrivenTest.login(DatadrivenTest.java:23)
	at sun.reflect.NativeMethodAccessorImpl.invoke0(Native Method)
	at sun.reflect.NativeMethodAccessorImpl.invoke(Unknown Source)
	at sun.reflect.DelegatingMethodAccessorImpl.invoke(Unknown Source)
	at java.lang.reflect.Method.invoke(Unknown Source)
	at org.testng.internal.MethodInvocationHelper.invokeMethod(MethodInvocationHelper.java:85)
	at org.testng.internal.Invoker.invokeMethod(Invoker.java:639)
	at org.testng.internal.Invoker.invokeTestMethod(Invoker.java:816)
	at org.testng.internal.Invoker.invokeTestMethods(Invoker.java:1124)
	at org.testng.internal.TestMethodWorker.invokeTestMethods(TestMethodWorker.java:125)
	at org.testng.internal.TestMethodWorker.run(TestMethodWorker.java:108)
	at org.testng.TestRunner.privateRun(TestRunner.java:774)
	at org.testng.TestRunner.run(TestRunner.java:624)
	at org.testng.SuiteRunner.runTest(SuiteRunner.java:359)
	at org.testng.SuiteRunner.runSequentially(SuiteRunner.java:354)
	at org.testng.SuiteRunner.privateRun(SuiteRunner.java:312)
	at org.testng.SuiteRunner.run(SuiteRunner.java:261)
	at org.testng.SuiteRunnerWorker.runSuite(SuiteRunnerWorker.java:52)
	at org.testng.SuiteRunnerWorker.run(SuiteRunnerWorker.java:86)
	at org.testng.TestNG.runSuitesSequentially(TestNG.java:1215)
	at org.testng.TestNG.runSuitesLocally(TestNG.java:1140)
	at org.testng.TestNG.run(TestNG.java:1048)
	at org.testng.remote.AbstractRemoteTestNG.run(AbstractRemoteTestNG.java:132)
	at org.testng.remote.RemoteTestNG.initAndRun(RemoteTestNG.java:236)
	at org.testng.remote.RemoteTestNG.main(RemoteTestNG.java:81)
Caused by: org.openqa.selenium.firefox.NotConnectedException: Unable to connect to host 127.0.0.1 on port 7055 after 45000 ms. Firefox console output:

	at org.openqa.selenium.firefox.internal.NewProfileExtensionConnection.start(NewProfileExtensionConnection.java:112)
	... 31 more
]]>
    </error>
  </testcase> <!-- login -->
  <testcase name="login" time="11.083" classname="datadriventesting.DatadrivenTest">
    <failure type="java.lang.AssertionError" message="expected [http://www.gcrit.com/build3/admin/login.php?action=process] but found [http://www.gcrit.com/build3/admin/index.php]">
      <![CDATA[java.lang.AssertionError: expected [http://www.gcrit.com/build3/admin/login.php?action=process] but found [http://www.gcrit.com/build3/admin/index.php]
	at org.testng.Assert.fail(Assert.java:94)
	at org.testng.Assert.failNotEquals(Assert.java:496)
	at org.testng.Assert.assertEquals(Assert.java:125)
	at org.testng.Assert.assertEquals(Assert.java:178)
	at org.testng.Assert.assertEquals(Assert.java:188)
	at datadriventesting.DatadrivenTest.login(DatadrivenTest.java:28)
	at sun.reflect.NativeMethodAccessorImpl.invoke0(Native Method)
	at sun.reflect.NativeMethodAccessorImpl.invoke(Unknown Source)
	at sun.reflect.DelegatingMethodAccessorImpl.invoke(Unknown Source)
	at java.lang.reflect.Method.invoke(Unknown Source)
	at org.testng.internal.MethodInvocationHelper.invokeMethod(MethodInvocationHelper.java:85)
	at org.testng.internal.Invoker.invokeMethod(Invoker.java:639)
	at org.testng.internal.Invoker.invokeTestMethod(Invoker.java:816)
	at org.testng.internal.Invoker.invokeTestMethods(Invoker.java:1124)
	at org.testng.internal.TestMethodWorker.invokeTestMethods(TestMethodWorker.java:125)
	at org.testng.internal.TestMethodWorker.run(TestMethodWorker.java:108)
	at org.testng.TestRunner.privateRun(TestRunner.java:774)
	at org.testng.TestRunner.run(TestRunner.java:624)
	at org.testng.SuiteRunner.runTest(SuiteRunner.java:359)
	at org.testng.SuiteRunner.runSequentially(SuiteRunner.java:354)
	at org.testng.SuiteRunner.privateRun(SuiteRunner.java:312)
	at org.testng.SuiteRunner.run(SuiteRunner.java:261)
	at org.testng.SuiteRunnerWorker.runSuite(SuiteRunnerWorker.java:52)
	at org.testng.SuiteRunnerWorker.run(SuiteRunnerWorker.java:86)
	at org.testng.TestNG.runSuitesSequentially(TestNG.java:1215)
	at org.testng.TestNG.runSuitesLocally(TestNG.java:1140)
	at org.testng.TestNG.run(TestNG.java:1048)
	at org.testng.remote.AbstractRemoteTestNG.run(AbstractRemoteTestNG.java:132)
	at org.testng.remote.RemoteTestNG.initAndRun(RemoteTestNG.java:236)
	at org.testng.remote.RemoteTestNG.main(RemoteTestNG.java:81)
]]>
    </failure>
  </testcase> <!-- login -->
  <testcase name="login" time="121.873" classname="datadriventesting.DatadrivenTest">
    <failure type="java.lang.AssertionError" message="expected [http://www.gcrit.com/build3/admin/login.php?action=process] but found [http://www.gcrit.com/build3/admin/index.php]">
      <![CDATA[java.lang.AssertionError: expected [http://www.gcrit.com/build3/admin/login.php?action=process] but found [http://www.gcrit.com/build3/admin/index.php]
	at org.testng.Assert.fail(Assert.java:94)
	at org.testng.Assert.failNotEquals(Assert.java:496)
	at org.testng.Assert.assertEquals(Assert.java:125)
	at org.testng.Assert.assertEquals(Assert.java:178)
	at org.testng.Assert.assertEquals(Assert.java:188)
	at datadriventesting.DatadrivenTest.login(DatadrivenTest.java:28)
	at sun.reflect.NativeMethodAccessorImpl.invoke0(Native Method)
	at sun.reflect.NativeMethodAccessorImpl.invoke(Unknown Source)
	at sun.reflect.DelegatingMethodAccessorImpl.invoke(Unknown Source)
	at java.lang.reflect.Method.invoke(Unknown Source)
	at org.testng.internal.MethodInvocationHelper.invokeMethod(MethodInvocationHelper.java:85)
	at org.testng.internal.Invoker.invokeMethod(Invoker.java:639)
	at org.testng.internal.Invoker.invokeTestMethod(Invoker.java:816)
	at org.testng.internal.Invoker.invokeTestMethods(Invoker.java:1124)
	at org.testng.internal.TestMethodWorker.invokeTestMethods(TestMethodWorker.java:125)
	at org.testng.internal.TestMethodWorker.run(TestMethodWorker.java:108)
	at org.testng.TestRunner.privateRun(TestRunner.java:774)
	at org.testng.TestRunner.run(TestRunner.java:624)
	at org.testng.SuiteRunner.runTest(SuiteRunner.java:359)
	at org.testng.SuiteRunner.runSequentially(SuiteRunner.java:354)
	at org.testng.SuiteRunner.privateRun(SuiteRunner.java:312)
	at org.testng.SuiteRunner.run(SuiteRunner.java:261)
	at org.testng.SuiteRunnerWorker.runSuite(SuiteRunnerWorker.java:52)
	at org.testng.SuiteRunnerWorker.run(SuiteRunnerWorker.java:86)
	at org.testng.TestNG.runSuitesSequentially(TestNG.java:1215)
	at org.testng.TestNG.runSuitesLocally(TestNG.java:1140)
	at org.testng.TestNG.run(TestNG.java:1048)
	at org.testng.remote.AbstractRemoteTestNG.run(AbstractRemoteTestNG.java:132)
	at org.testng.remote.RemoteTestNG.initAndRun(RemoteTestNG.java:236)
	at org.testng.remote.RemoteTestNG.main(RemoteTestNG.java:81)
]]>
    </failure>
  </testcase> <!-- login -->
  <testcase name="login" time="47.974" classname="datadriventesting.DatadrivenTest">
    <failure type="java.lang.AssertionError" message="expected [http://www.gcrit.com/build3/admin/login.php?action=process] but found [http://www.gcrit.com/build3/admin/index.php]">
      <![CDATA[java.lang.AssertionError: expected [http://www.gcrit.com/build3/admin/login.php?action=process] but found [http://www.gcrit.com/build3/admin/index.php]
	at org.testng.Assert.fail(Assert.java:94)
	at org.testng.Assert.failNotEquals(Assert.java:496)
	at org.testng.Assert.assertEquals(Assert.java:125)
	at org.testng.Assert.assertEquals(Assert.java:178)
	at org.testng.Assert.assertEquals(Assert.java:188)
	at datadriventesting.DatadrivenTest.login(DatadrivenTest.java:28)
	at sun.reflect.NativeMethodAccessorImpl.invoke0(Native Method)
	at sun.reflect.NativeMethodAccessorImpl.invoke(Unknown Source)
	at sun.reflect.DelegatingMethodAccessorImpl.invoke(Unknown Source)
	at java.lang.reflect.Method.invoke(Unknown Source)
	at org.testng.internal.MethodInvocationHelper.invokeMethod(MethodInvocationHelper.java:85)
	at org.testng.internal.Invoker.invokeMethod(Invoker.java:639)
	at org.testng.internal.Invoker.invokeTestMethod(Invoker.java:816)
	at org.testng.internal.Invoker.invokeTestMethods(Invoker.java:1124)
	at org.testng.internal.TestMethodWorker.invokeTestMethods(TestMethodWorker.java:125)
	at org.testng.internal.TestMethodWorker.run(TestMethodWorker.java:108)
	at org.testng.TestRunner.privateRun(TestRunner.java:774)
	at org.testng.TestRunner.run(TestRunner.java:624)
	at org.testng.SuiteRunner.runTest(SuiteRunner.java:359)
	at org.testng.SuiteRunner.runSequentially(SuiteRunner.java:354)
	at org.testng.SuiteRunner.privateRun(SuiteRunner.java:312)
	at org.testng.SuiteRunner.run(SuiteRunner.java:261)
	at org.testng.SuiteRunnerWorker.runSuite(SuiteRunnerWorker.java:52)
	at org.testng.SuiteRunnerWorker.run(SuiteRunnerWorker.java:86)
	at org.testng.TestNG.runSuitesSequentially(TestNG.java:1215)
	at org.testng.TestNG.runSuitesLocally(TestNG.java:1140)
	at org.testng.TestNG.run(TestNG.java:1048)
	at org.testng.remote.AbstractRemoteTestNG.run(AbstractRemoteTestNG.java:132)
	at org.testng.remote.RemoteTestNG.initAndRun(RemoteTestNG.java:236)
	at org.testng.remote.RemoteTestNG.main(RemoteTestNG.java:81)
]]>
    </failure>
  </testcase> <!-- login -->
</testsuite> <!-- datadriventesting.DatadrivenTest -->
